ISSUE #001: Error when using this function within app/main.py:

# Example endpoint which is using authentification (auth.py)
@app.get("/user")
async def read_users_me(user: AuthenticatedUser = Depends(auth.authenticated())):
    return {"user": user}

DETAIL #001:
Traceback (most recent call last):
  File "/usr/local/lib/python3.11/multiprocessing/process.py", line 314, in _bootstrap
    self.run()
  File "/usr/local/lib/python3.11/multiprocessing/process.py", line 108, in run
    self._target(*self._args, **self._kwargs)
  File "/usr/local/lib/python3.11/site-packages/uvicorn/_subprocess.py", line 78, in subprocess_started
    target(sockets=sockets)
  File "/usr/local/lib/python3.11/site-packages/uvicorn/server.py", line 62, in run
    return asyncio.run(self.serve(sockets=sockets))
           ^^^^^^^^^^^^^^^^^^^^^^^^^^^^^^^^^^^^^^^^
  File "/usr/local/lib/python3.11/asyncio/runners.py", line 190, in run
    return runner.run(main)
           ^^^^^^^^^^^^^^^^
  File "/usr/local/lib/python3.11/asyncio/runners.py", line 118, in run
    return self._loop.run_until_complete(task)
           ^^^^^^^^^^^^^^^^^^^^^^^^^^^^^^^^^^^
  File "/usr/local/lib/python3.11/asyncio/base_events.py", line 653, in run_until_complete
    return future.result()
           ^^^^^^^^^^^^^^^
  File "/usr/local/lib/python3.11/site-packages/uvicorn/server.py", line 69, in serve
    config.load()
  File "/usr/local/lib/python3.11/site-packages/uvicorn/config.py", line 458, in load
    self.loaded_app = import_from_string(self.app)
                      ^^^^^^^^^^^^^^^^^^^^^^^^^^^^
  File "/usr/local/lib/python3.11/site-packages/uvicorn/importer.py", line 21, in import_from_string
    module = importlib.import_module(module_str)
             ^^^^^^^^^^^^^^^^^^^^^^^^^^^^^^^^^^^
  File "/usr/local/lib/python3.11/importlib/__init__.py", line 126, in import_module
    return _bootstrap._gcd_import(name[level:], package, level)
           ^^^^^^^^^^^^^^^^^^^^^^^^^^^^^^^^^^^^^^^^^^^^^^^^^^^^
  File "<frozen importlib._bootstrap>", line 1206, in _gcd_import
  File "<frozen importlib._bootstrap>", line 1178, in _find_and_load
  File "<frozen importlib._bootstrap>", line 1149, in _find_and_load_unlocked
  File "<frozen importlib._bootstrap>", line 690, in _load_unlocked
  File "<frozen importlib._bootstrap_external>", line 940, in exec_module
  File "<frozen importlib._bootstrap>", line 241, in _call_with_frames_removed
  File "/code/app/main.py", line 19, in <module>
    @app.get("/user")
     ^^^^^^^^^^^^^^^^
  File "/usr/local/lib/python3.11/site-packages/fastapi/routing.py", line 956, in decorator
    self.add_api_route(
  File "/usr/local/lib/python3.11/site-packages/fastapi/routing.py", line 895, in add_api_route
    route = route_class(
            ^^^^^^^^^^^^
  File "/usr/local/lib/python3.11/site-packages/fastapi/routing.py", line 525, in __init__
    self.dependant = get_dependant(path=self.path_format, call=self.endpoint)
                     ^^^^^^^^^^^^^^^^^^^^^^^^^^^^^^^^^^^^^^^^^^^^^^^^^^^^^^^^
  File "/usr/local/lib/python3.11/site-packages/fastapi/dependencies/utils.py", line 261, in get_dependant
    type_annotation, depends, param_field = analyze_param(
                                            ^^^^^^^^^^^^^^
  File "/usr/local/lib/python3.11/site-packages/fastapi/dependencies/utils.py", line 368, in analyze_param
    assert depends is None, (
           ^^^^^^^^^^^^^^^
AssertionError: Cannot specify `Depends` in `Annotated` and default value together for 'user'

SOLUTION #001:
Status: Open
Note: Ask in the fief discussion round

----------------------------------------------
